# 🔧 远端环境评估问题修复指南

## 🚨 问题描述

**症状**：
- ✅ 评估功能正常完成，后端日志显示记录已保存
- ❌ 前端显示评估完成后，用户无法看到保存的记录
- ❌ 点击"人工评估"时报错："评估记录不存在"
- ❌ 浏览器控制台显示：`POST /api/evaluation-history 405 (Method Not Allowed)`

## 🔍 问题根因

1. **重复保存问题**：前端在评估完成后尝试额外保存记录，但后端缺少对应的POST路由
2. **记录查询问题**：人工评估时无法正确获取到评估记录ID
3. **数据序列化问题**：评估记录的日期字段格式不一致

## ⚡ 快速修复（推荐）

### 步骤1：运行诊断修复工具

```bash
# 进入后端目录
cd backend

# 运行诊断和修复脚本
python fix_remote_evaluation_issues.py
```

### 步骤2：重启后端服务

```bash
# 停止当前后端服务（Ctrl+C）
# 然后重启
python app.py
```

### 步骤3：验证修复效果

1. **测试评估保存**：
   - 执行一次完整的问答评估
   - 检查浏览器控制台是否还有405错误
   - 确认评估记录正常保存

2. **测试人工评估**：
   - 进入"评估历史"页面
   - 选择一条记录点击"人工评估"
   - 确认能正常打开人工评估弹窗
   - 修改分数后保存，确认保存成功

## 🛠️ 手动修复（备选方案）

### 修复1：添加POST路由

在 `backend/app.py` 的评估历史路由部分添加：

```python
@app.route('/api/evaluation-history', methods=['POST'])
def save_evaluation_history():
    """保存评估历史记录（兼容前端重复保存调用）"""
    try:
        logger.info("前端尝试保存评估历史记录")
        
        data = request.get_json()
        
        # 检查是否已经存在相同的记录（避免重复）
        if data.get('user_input') and data.get('model_answer'):
            existing = EvaluationHistory.query.filter_by(
                user_input=data['user_input'],
                model_answer=data['model_answer']
            ).order_by(EvaluationHistory.created_at.desc()).first()
            
            # 如果最近2分钟内有相同记录，返回现有记录
            if existing and (datetime.utcnow() - existing.created_at).seconds < 120:
                logger.info(f"发现重复记录，返回现有记录ID: {existing.id}")
                return jsonify({
                    'success': True,
                    'message': '记录已存在，返回现有记录',
                    'history_id': existing.id,
                    'data': existing.to_dict()
                })
        
        # 调用服务保存记录
        result = evaluation_history_service.save_evaluation_result(data)
        
        return jsonify(result)
        
    except Exception as e:
        logger.error(f"保存评估历史失败: {str(e)}")
        return jsonify({'error': f'保存评估历史失败: {str(e)}'}), 500
```

### 修复2：检查数据库表结构

```bash
# 进入Python环境
python

# 检查数据库表
from app import app
from models.classification import db, EvaluationHistory

with app.app_context():
    # 查看最新记录
    records = EvaluationHistory.query.order_by(EvaluationHistory.id.desc()).limit(5).all()
    for r in records:
        print(f"ID: {r.id}, Score: {r.total_score}, Created: {r.created_at}")
```

## 📊 修复验证清单

### ✅ 后端检查

- [ ] POST `/api/evaluation-history` 路由存在且可访问
- [ ] 评估记录正常保存到数据库
- [ ] `EvaluationHistory.to_dict()` 方法正常工作
- [ ] 人工评估更新API正常工作

### ✅ 前端检查

- [ ] 评估完成后无405错误
- [ ] 评估历史页面能正常显示记录
- [ ] 人工评估弹窗能正常打开
- [ ] 人工评估保存功能正常

### ✅ 数据一致性检查

- [ ] 数据库中的评估记录数量正确
- [ ] 前端显示的记录与数据库一致
- [ ] 日期字段格式正确
- [ ] JSON字段序列化/反序列化正常

## 🔍 问题排查

### 如果问题仍然存在：

1. **检查日志**：
   ```bash
   # 查看详细错误日志
   tail -f backend/logs/app.log
   ```

2. **检查数据库连接**：
   ```python
   # 测试数据库连接
   from app import app
   from models.classification import db
   
   with app.app_context():
       print(f"数据库URL: {app.config['SQLALCHEMY_DATABASE_URI']}")
       print(f"连接状态: {db.engine.execute('SELECT 1').scalar()}")
   ```

3. **清除浏览器缓存**：
   - 按F12打开开发者工具
   - 右键刷新按钮，选择"清空缓存并硬性重新加载"

4. **检查网络请求**：
   - 在浏览器开发者工具的Network标签页
   - 查看所有API请求的状态码和响应内容

## 📞 获取帮助

如果按照以上步骤仍无法解决问题，请提供：

1. **诊断脚本输出**：运行 `python fix_remote_evaluation_issues.py` 的完整输出
2. **错误日志**：后端 `logs/app.log` 中的相关错误信息
3. **浏览器控制台错误**：包括Network请求的状态码和响应内容
4. **数据库状态**：最新评估记录的数量和内容

---

## 📝 更新日志

- **v1.0** (2025-06-03): 初始版本，解决远端环境评估记录保存和人工评估问题
- 修复POST `/api/evaluation-history` 405错误
- 修复人工评估"记录不存在"问题
- 新增自动诊断和修复工具 